package com.test.myMod.WorldGen;



import net.minecraft.block.Block;
import net.minecraft.init.Blocks;
import net.minecraft.world.World;
import net.minecraft.world.biome.BiomeGenBase;

import java.util.Random;

public class HutGeneration {

    public Object instance;

    public HutGeneration(){}
    Blocks b;

    public void load(){
    }


    public void generateSurface(World world, Random random, int i2, int k2){

        int i = i2 + random.nextInt(15);
        int k = k2 + random.nextInt(15);

        int j = world.getHeightValue(i,k)-1;
        if(world.getBiomeGenForCoords(i, k).biomeName.equals(BiomeGenBase.plains.biomeName)) {


            if((random.nextInt(1000000)+1)<=100000){
                boolean place = true;

                for (int y = 0; y<10; y++)
                    for (int z = 0; z<11; z++)
                        for (int x = 0; x<11; x++)
                            if(world.getBlock(i+x,j+y+1,k+z)!= Blocks.air)
                                place = false;

                if(place){

                    world.setBlock(i+0, j+0, k+0, b.grass, 0, 2);
                    world.setBlock(i+1, j+0, k+0, b.grass, 0, 2);
                    world.setBlock(i+2, j+0, k+0, b.grass, 0, 2);
                    world.setBlock(i+3, j+0, k+0, b.grass, 0, 2);
                    world.setBlock(i+4, j+0, k+0, b.grass, 0, 2);
                    world.setBlock(i+5, j+0, k+0, b.grass, 0, 2);
                    world.setBlock(i+6, j+0, k+0, b.grass, 0, 2);
                    world.setBlock(i+7, j+0, k+0, b.grass, 0, 2);
                    world.setBlock(i+8, j+0, k+0, b.grass, 0, 2);
                    world.setBlock(i+9, j+0, k+0, b.grass, 0, 2);
                    world.setBlock(i+10, j+0, k+0, b.grass, 0, 2);
                    world.setBlock(i+0, j+0, k+1, b.grass, 0, 2);
                    world.setBlock(i+1, j+0, k+1, b.planks, 1, 2);
                    world.setBlock(i+2, j+0, k+1, b.planks, 1, 2);
                    world.setBlock(i+3, j+0, k+1, b.planks, 1, 2);
                    world.setBlock(i+4, j+0, k+1, b.planks, 1, 2);
                    world.setBlock(i+5, j+0, k+1, b.planks, 1, 2);
                    world.setBlock(i+6, j+0, k+1, b.planks, 1, 2);
                    world.setBlock(i+7, j+0, k+1, b.planks, 1, 2);
                    world.setBlock(i+8, j+0, k+1, b.planks, 1, 2);
                    world.setBlock(i+9, j+0, k+1, b.planks, 1, 2);
                    world.setBlock(i+10, j+0, k+1, b.grass, 0, 2);
                    world.setBlock(i+0, j+0, k+2, b.grass, 0, 2);
                    world.setBlock(i+1, j+0, k+2, b.planks, 1, 2);
                    world.setBlock(i+2, j+0, k+2, b.planks, 1, 2);
                    world.setBlock(i+3, j+0, k+2, b.planks, 1, 2);
                    world.setBlock(i+4, j+0, k+2, b.planks, 1, 2);
                    world.setBlock(i+5, j+0, k+2, b.planks, 1, 2);
                    world.setBlock(i+6, j+0, k+2, b.planks, 1, 2);
                    world.setBlock(i+7, j+0, k+2, b.planks, 1, 2);
                    world.setBlock(i+8, j+0, k+2, b.planks, 1, 2);
                    world.setBlock(i+9, j+0, k+2, b.planks, 1, 2);
                    world.setBlock(i+10, j+0, k+2, b.grass, 0, 2);
                    world.setBlock(i+0, j+0, k+3, b.grass, 0, 2);
                    world.setBlock(i+1, j+0, k+3, b.planks, 1, 2);
                    world.setBlock(i+2, j+0, k+3, b.planks, 1, 2);
                    world.setBlock(i+3, j+0, k+3, b.planks, 1, 2);
                    world.setBlock(i+4, j+0, k+3, b.planks, 1, 2);
                    world.setBlock(i+5, j+0, k+3, b.planks, 1, 2);
                    world.setBlock(i+6, j+0, k+3, b.planks, 1, 2);
                    world.setBlock(i+7, j+0, k+3, b.planks, 1, 2);
                    world.setBlock(i+8, j+0, k+3, b.planks, 1, 2);
                    world.setBlock(i+9, j+0, k+3, b.planks, 1, 2);
                    world.setBlock(i+10, j+0, k+3, b.grass, 0, 2);
                    world.setBlock(i+0, j+0, k+4, b.grass, 0, 2);
                    world.setBlock(i+1, j+0, k+4, b.planks, 1, 2);
                    world.setBlock(i+2, j+0, k+4, b.planks, 1, 2);
                    world.setBlock(i+3, j+0, k+4, b.planks, 1, 2);
                    world.setBlock(i+4, j+0, k+4, b.planks, 1, 2);
                    world.setBlock(i+5, j+0, k+4, b.planks, 1, 2);
                    world.setBlock(i+6, j+0, k+4, b.planks, 1, 2);
                    world.setBlock(i+7, j+0, k+4, b.planks, 1, 2);
                    world.setBlock(i+8, j+0, k+4, b.planks, 1, 2);
                    world.setBlock(i+9, j+0, k+4, b.planks, 1, 2);
                    world.setBlock(i+10, j+0, k+4, b.grass, 0, 2);
                    world.setBlock(i+0, j+0, k+5, b.grass, 0, 2);
                    world.setBlock(i+1, j+0, k+5, b.planks, 1, 2);
                    world.setBlock(i+2, j+0, k+5, b.planks, 1, 2);
                    world.setBlock(i+3, j+0, k+5, b.planks, 1, 2);
                    world.setBlock(i+4, j+0, k+5, b.planks, 1, 2);
                    world.setBlock(i+5, j+0, k+5, b.planks, 1, 2);
                    world.setBlock(i+6, j+0, k+5, b.planks, 1, 2);
                    world.setBlock(i+7, j+0, k+5, b.planks, 1, 2);
                    world.setBlock(i+8, j+0, k+5, b.planks, 1, 2);
                    world.setBlock(i+9, j+0, k+5, b.planks, 1, 2);
                    world.setBlock(i+10, j+0, k+5, b.grass, 0, 2);
                    world.setBlock(i+0, j+0, k+6, b.grass, 0, 2);
                    world.setBlock(i+1, j+0, k+6, b.planks, 1, 2);
                    world.setBlock(i+2, j+0, k+6, b.planks, 1, 2);
                    world.setBlock(i+3, j+0, k+6, b.planks, 1, 2);
                    world.setBlock(i+4, j+0, k+6, b.planks, 1, 2);
                    world.setBlock(i+5, j+0, k+6, b.planks, 1, 2);
                    world.setBlock(i+6, j+0, k+6, b.planks, 1, 2);
                    world.setBlock(i+7, j+0, k+6, b.planks, 1, 2);
                    world.setBlock(i+8, j+0, k+6, b.planks, 1, 2);
                    world.setBlock(i+9, j+0, k+6, b.planks, 1, 2);
                    world.setBlock(i+10, j+0, k+6, b.grass, 0, 2);
                    world.setBlock(i+0, j+0, k+7, b.grass, 0, 2);
                    world.setBlock(i+1, j+0, k+7, b.planks, 1, 2);
                    world.setBlock(i+2, j+0, k+7, b.planks, 1, 2);
                    world.setBlock(i+3, j+0, k+7, b.planks, 1, 2);
                    world.setBlock(i+4, j+0, k+7, b.planks, 1, 2);
                    world.setBlock(i+5, j+0, k+7, b.planks, 1, 2);
                    world.setBlock(i+6, j+0, k+7, b.planks, 1, 2);
                    world.setBlock(i+7, j+0, k+7, b.planks, 1, 2);
                    world.setBlock(i+8, j+0, k+7, b.planks, 1, 2);
                    world.setBlock(i+9, j+0, k+7, b.planks, 1, 2);
                    world.setBlock(i+10, j+0, k+7, b.grass, 0, 2);
                    world.setBlock(i+0, j+0, k+8, b.grass, 0, 2);
                    world.setBlock(i+1, j+0, k+8, b.planks, 1, 2);
                    world.setBlock(i+2, j+0, k+8, b.planks, 1, 2);
                    world.setBlock(i+3, j+0, k+8, b.planks, 1, 2);
                    world.setBlock(i+4, j+0, k+8, b.planks, 1, 2);
                    world.setBlock(i+5, j+0, k+8, b.planks, 1, 2);
                    world.setBlock(i+6, j+0, k+8, b.planks, 1, 2);
                    world.setBlock(i+7, j+0, k+8, b.planks, 1, 2);
                    world.setBlock(i+8, j+0, k+8, b.planks, 1, 2);
                    world.setBlock(i+9, j+0, k+8, b.planks, 1, 2);
                    world.setBlock(i+10, j+0, k+8, b.grass, 0, 2);
                    world.setBlock(i+0, j+0, k+9, b.grass, 0, 2);
                    world.setBlock(i+1, j+0, k+9, b.planks, 1, 2);
                    world.setBlock(i+2, j+0, k+9, b.planks, 1, 2);
                    world.setBlock(i+3, j+0, k+9, b.planks, 1, 2);
                    world.setBlock(i+4, j+0, k+9, b.planks, 1, 2);
                    world.setBlock(i+5, j+0, k+9, b.planks, 1, 2);
                    world.setBlock(i+6, j+0, k+9, b.planks, 1, 2);
                    world.setBlock(i+7, j+0, k+9, b.planks, 1, 2);
                    world.setBlock(i+8, j+0, k+9, b.planks, 1, 2);
                    world.setBlock(i+9, j+0, k+9, b.planks, 1, 2);
                    world.setBlock(i+10, j+0, k+9, b.grass, 0, 2);
                    world.setBlock(i+0, j+0, k+10, b.grass, 0, 2);
                    world.setBlock(i+1, j+0, k+10, b.grass, 0, 2);
                    world.setBlock(i+2, j+0, k+10, b.grass, 0, 2);
                    world.setBlock(i+3, j+0, k+10, b.grass, 0, 2);
                    world.setBlock(i+4, j+0, k+10, b.grass, 0, 2);
                    world.setBlock(i+5, j+0, k+10, b.grass, 0, 2);
                    world.setBlock(i+6, j+0, k+10, b.grass, 0, 2);
                    world.setBlock(i+7, j+0, k+10, b.grass, 0, 2);
                    world.setBlock(i+8, j+0, k+10, b.grass, 0, 2);
                    world.setBlock(i+9, j+0, k+10, b.grass, 0, 2);
                    world.setBlock(i+10, j+0, k+10, b.grass, 0, 2);
                    world.setBlock(i+1, j+1, k+1, b.fence, 0, 2);
                    world.setBlock(i+2, j+1, k+1, b.fence, 0, 2);
                    world.setBlock(i+8, j+1, k+1, b.fence, 0, 2);
                    world.setBlock(i+9, j+1, k+1, b.fence, 0, 2);
                    world.setBlock(i+1, j+1, k+2, b.fence, 0, 2);
                    world.setBlock(i+9, j+1, k+2, b.fence, 0, 2);
                    world.setBlock(i+1, j+1, k+8, b.fence, 0, 2);
                    world.setBlock(i+9, j+1, k+8, b.fence, 0, 2);
                    world.setBlock(i+1, j+1, k+9, b.fence, 0, 2);
                    world.setBlock(i+2, j+1, k+9, b.fence, 0, 2);
                    world.setBlock(i+8, j+1, k+9, b.fence, 0, 2);
                    world.setBlock(i+9, j+1, k+9, b.fence, 0, 2);
                    world.setBlock(i+1, j+2, k+1, b.fence, 0, 2);
                    world.setBlock(i+9, j+2, k+1, b.fence, 0, 2);
                    world.setBlock(i+1, j+2, k+9, b.fence, 0, 2);
                    world.setBlock(i+9, j+2, k+9, b.fence, 0, 2);
                    world.setBlock(i+1, j+3, k+1, b.fence, 0, 2);
                    world.setBlock(i+9, j+3, k+1, b.fence, 0, 2);
                    world.setBlock(i+5, j+3, k+5, b.planks, 1, 2);
                    world.setBlock(i+5, j+3, k+4, b.torch, 4, 2);
                    world.setBlock(i+4, j+3, k+5, b.torch, 2, 2);
                    world.setBlock(i+6, j+3, k+5, b.torch, 1, 2);
                    world.setBlock(i+5, j+3, k+6, b.torch, 3, 2);
                    world.setBlock(i+1, j+3, k+9, b.fence, 0, 2);
                    world.setBlock(i+9, j+3, k+9, b.fence, 0, 2);
                    world.setBlock(i+1, j+4, k+1, b.fence, 0, 2);
                    world.setBlock(i+2, j+4, k+1, b.fence, 0, 2);
                    world.setBlock(i+8, j+4, k+1, b.fence, 0, 2);
                    world.setBlock(i+9, j+4, k+1, b.fence, 0, 2);
                    world.setBlock(i+1, j+4, k+2, b.fence, 0, 2);
                    world.setBlock(i+9, j+4, k+2, b.fence, 0, 2);
                    world.setBlock(i+5, j+4, k+5, b.fence, 0, 2);
                    world.setBlock(i+1, j+4, k+8, b.fence, 0, 2);
                    world.setBlock(i+9, j+4, k+8, b.fence, 0, 2);
                    world.setBlock(i+1, j+4, k+9, b.fence, 0, 2);
                    world.setBlock(i+2, j+4, k+9, b.fence, 0, 2);
                    world.setBlock(i+8, j+4, k+9, b.fence, 0, 2);
                    world.setBlock(i+9, j+4, k+9, b.fence, 0, 2);
                    world.setBlock(i+0, j+5, k+0, b.spruce_stairs, 2, 2);
                    world.setBlock(i+1, j+5, k+0, b.spruce_stairs, 2, 2);
                    world.setBlock(i+2, j+5, k+0, b.spruce_stairs, 2, 2);
                    world.setBlock(i+3, j+5, k+0, b.spruce_stairs, 2, 2);
                    world.setBlock(i+4, j+5, k+0, b.spruce_stairs, 2, 2);
                    world.setBlock(i+5, j+5, k+0, b.spruce_stairs, 2, 2);
                    world.setBlock(i+6, j+5, k+0, b.spruce_stairs, 2, 2);
                    world.setBlock(i+7, j+5, k+0, b.spruce_stairs, 2, 2);
                    world.setBlock(i+8, j+5, k+0, b.spruce_stairs, 2, 2);
                    world.setBlock(i+9, j+5, k+0, b.spruce_stairs, 2, 2);
                    world.setBlock(i+10, j+5, k+0, b.spruce_stairs, 1, 2);
                    world.setBlock(i+0, j+5, k+1, b.spruce_stairs, 0, 2);
                    world.setBlock(i+1, j+5, k+1, b.planks, 1, 2);
                    world.setBlock(i+2, j+5, k+1, b.planks, 1, 2);
                    world.setBlock(i+3, j+5, k+1, b.planks, 1, 2);
                    world.setBlock(i+4, j+5, k+1, b.planks, 1, 2);
                    world.setBlock(i+5, j+5, k+1, b.planks, 1, 2);
                    world.setBlock(i+6, j+5, k+1, b.planks, 1, 2);
                    world.setBlock(i+7, j+5, k+1, b.planks, 1, 2);
                    world.setBlock(i+8, j+5, k+1, b.planks, 1, 2);
                    world.setBlock(i+9, j+5, k+1, b.planks, 1, 2);
                    world.setBlock(i+10, j+5, k+1, b.spruce_stairs, 1, 2);
                    world.setBlock(i+0, j+5, k+2, b.spruce_stairs, 0, 2);
                    world.setBlock(i+1, j+5, k+2, b.planks, 1, 2);
                    world.setBlock(i+2, j+5, k+2, b.planks, 1, 2);
                    world.setBlock(i+3, j+5, k+2, b.planks, 1, 2);
                    world.setBlock(i+4, j+5, k+2, b.planks, 1, 2);
                    world.setBlock(i+5, j+5, k+2, b.planks, 1, 2);
                    world.setBlock(i+6, j+5, k+2, b.planks, 1, 2);
                    world.setBlock(i+7, j+5, k+2, b.planks, 1, 2);
                    world.setBlock(i+8, j+5, k+2, b.planks, 1, 2);
                    world.setBlock(i+9, j+5, k+2, b.planks, 1, 2);
                    world.setBlock(i+10, j+5, k+2, b.spruce_stairs, 1, 2);
                    world.setBlock(i+0, j+5, k+3, b.spruce_stairs, 0, 2);
                    world.setBlock(i+1, j+5, k+3, b.planks, 1, 2);
                    world.setBlock(i+2, j+5, k+3, b.planks, 1, 2);
                    world.setBlock(i+3, j+5, k+3, b.planks, 1, 2);
                    world.setBlock(i+4, j+5, k+3, b.planks, 1, 2);
                    world.setBlock(i+5, j+5, k+3, b.planks, 1, 2);
                    world.setBlock(i+6, j+5, k+3, b.planks, 1, 2);
                    world.setBlock(i+7, j+5, k+3, b.planks, 1, 2);
                    world.setBlock(i+8, j+5, k+3, b.planks, 1, 2);
                    world.setBlock(i+9, j+5, k+3, b.planks, 1, 2);
                    world.setBlock(i+10, j+5, k+3, b.spruce_stairs, 1, 2);
                    world.setBlock(i+0, j+5, k+4, b.spruce_stairs, 0, 2);
                    world.setBlock(i+1, j+5, k+4, b.planks, 1, 2);
                    world.setBlock(i+2, j+5, k+4, b.planks, 1, 2);
                    world.setBlock(i+3, j+5, k+4, b.planks, 1, 2);
                    world.setBlock(i+4, j+5, k+4, b.planks, 1, 2);
                    world.setBlock(i+5, j+5, k+4, b.planks, 1, 2);
                    world.setBlock(i+6, j+5, k+4, b.planks, 1, 2);
                    world.setBlock(i+7, j+5, k+4, b.planks, 1, 2);
                    world.setBlock(i+8, j+5, k+4, b.planks, 1, 2);
                    world.setBlock(i+9, j+5, k+4, b.planks, 1, 2);
                    world.setBlock(i+10, j+5, k+4, b.spruce_stairs, 1, 2);
                    world.setBlock(i+0, j+5, k+5, b.spruce_stairs, 0, 2);
                    world.setBlock(i+1, j+5, k+5, b.planks, 1, 2);
                    world.setBlock(i+2, j+5, k+5, b.planks, 1, 2);
                    world.setBlock(i+3, j+5, k+5, b.planks, 1, 2);
                    world.setBlock(i+4, j+5, k+5, b.planks, 1, 2);
                    world.setBlock(i+5, j+5, k+5, b.planks, 1, 2);
                    world.setBlock(i+6, j+5, k+5, b.planks, 1, 2);
                    world.setBlock(i+7, j+5, k+5, b.planks, 1, 2);
                    world.setBlock(i+8, j+5, k+5, b.planks, 1, 2);
                    world.setBlock(i+9, j+5, k+5, b.planks, 1, 2);
                    world.setBlock(i+10, j+5, k+5, b.spruce_stairs, 1, 2);
                    world.setBlock(i+0, j+5, k+6, b.spruce_stairs, 0, 2);
                    world.setBlock(i+1, j+5, k+6, b.planks, 1, 2);
                    world.setBlock(i+2, j+5, k+6, b.planks, 1, 2);
                    world.setBlock(i+3, j+5, k+6, b.planks, 1, 2);
                    world.setBlock(i+4, j+5, k+6, b.planks, 1, 2);
                    world.setBlock(i+5, j+5, k+6, b.planks, 1, 2);
                    world.setBlock(i+6, j+5, k+6, b.planks, 1, 2);
                    world.setBlock(i+7, j+5, k+6, b.planks, 1, 2);
                    world.setBlock(i+8, j+5, k+6, b.planks, 1, 2);
                    world.setBlock(i+9, j+5, k+6, b.planks, 1, 2);
                    world.setBlock(i+10, j+5, k+6, b.spruce_stairs, 1, 2);
                    world.setBlock(i+0, j+5, k+7, b.spruce_stairs, 0, 2);
                    world.setBlock(i+1, j+5, k+7, b.planks, 1, 2);
                    world.setBlock(i+2, j+5, k+7, b.planks, 1, 2);
                    world.setBlock(i+3, j+5, k+7, b.planks, 1, 2);
                    world.setBlock(i+4, j+5, k+7, b.planks, 1, 2);
                    world.setBlock(i+5, j+5, k+7, b.planks, 1, 2);
                    world.setBlock(i+6, j+5, k+7, b.planks, 1, 2);
                    world.setBlock(i+7, j+5, k+7, b.planks, 1, 2);
                    world.setBlock(i+8, j+5, k+7, b.planks, 1, 2);
                    world.setBlock(i+9, j+5, k+7, b.planks, 1, 2);
                    world.setBlock(i+10, j+5, k+7, b.spruce_stairs, 1, 2);
                    world.setBlock(i+0, j+5, k+8, b.spruce_stairs, 0, 2);
                    world.setBlock(i+1, j+5, k+8, b.planks, 1, 2);
                    world.setBlock(i+2, j+5, k+8, b.planks, 1, 2);
                    world.setBlock(i+3, j+5, k+8, b.planks, 1, 2);
                    world.setBlock(i+4, j+5, k+8, b.planks, 1, 2);
                    world.setBlock(i+5, j+5, k+8, b.planks, 1, 2);
                    world.setBlock(i+6, j+5, k+8, b.planks, 1, 2);
                    world.setBlock(i+7, j+5, k+8, b.planks, 1, 2);
                    world.setBlock(i+8, j+5, k+8, b.planks, 1, 2);
                    world.setBlock(i+9, j+5, k+8, b.planks, 1, 2);
                    world.setBlock(i+10, j+5, k+8, b.spruce_stairs, 1, 2);
                    world.setBlock(i+0, j+5, k+9, b.spruce_stairs, 0, 2);
                    world.setBlock(i+1, j+5, k+9, b.planks, 1, 2);
                    world.setBlock(i+2, j+5, k+9, b.planks, 1, 2);
                    world.setBlock(i+3, j+5, k+9, b.planks, 1, 2);
                    world.setBlock(i+4, j+5, k+9, b.planks, 1, 2);
                    world.setBlock(i+5, j+5, k+9, b.planks, 1, 2);
                    world.setBlock(i+6, j+5, k+9, b.planks, 1, 2);
                    world.setBlock(i+7, j+5, k+9, b.planks, 1, 2);
                    world.setBlock(i+8, j+5, k+9, b.planks, 1, 2);
                    world.setBlock(i+9, j+5, k+9, b.planks, 1, 2);
                    world.setBlock(i+10, j+5, k+9, b.spruce_stairs, 1, 2);
                    world.setBlock(i+0, j+5, k+10, b.spruce_stairs, 0, 2);
                    world.setBlock(i+1, j+5, k+10, b.spruce_stairs, 3, 2);
                    world.setBlock(i+2, j+5, k+10, b.spruce_stairs, 3, 2);
                    world.setBlock(i+3, j+5, k+10, b.spruce_stairs, 3, 2);
                    world.setBlock(i+4, j+5, k+10, b.spruce_stairs, 3, 2);
                    world.setBlock(i+5, j+5, k+10, b.spruce_stairs, 3, 2);
                    world.setBlock(i+6, j+5, k+10, b.spruce_stairs, 3, 2);
                    world.setBlock(i+7, j+5, k+10, b.spruce_stairs, 3, 2);
                    world.setBlock(i+8, j+5, k+10, b.spruce_stairs, 3, 2);
                    world.setBlock(i+9, j+5, k+10, b.spruce_stairs, 3, 2);
                    world.setBlock(i+10, j+5, k+10, b.spruce_stairs, 3, 2);
                    world.setBlock(i+1, j+6, k+1, b.spruce_stairs, 0, 2);
                    world.setBlock(i+2, j+6, k+1, b.spruce_stairs, 2, 2);
                    world.setBlock(i+3, j+6, k+1, b.spruce_stairs, 2, 2);
                    world.setBlock(i+4, j+6, k+1, b.spruce_stairs, 2, 2);
                    world.setBlock(i+5, j+6, k+1, b.spruce_stairs, 2, 2);
                    world.setBlock(i+6, j+6, k+1, b.spruce_stairs, 2, 2);
                    world.setBlock(i+7, j+6, k+1, b.spruce_stairs, 2, 2);
                    world.setBlock(i+8, j+6, k+1, b.spruce_stairs, 2, 2);
                    world.setBlock(i+9, j+6, k+1, b.spruce_stairs, 2, 2);
                    world.setBlock(i+1, j+6, k+2, b.spruce_stairs, 0, 2);
                    world.setBlock(i+2, j+6, k+2, b.planks, 1, 2);
                    world.setBlock(i+3, j+6, k+2, b.planks, 1, 2);
                    world.setBlock(i+4, j+6, k+2, b.planks, 1, 2);
                    world.setBlock(i+5, j+6, k+2, b.planks, 1, 2);
                    world.setBlock(i+6, j+6, k+2, b.planks, 1, 2);
                    world.setBlock(i+7, j+6, k+2, b.planks, 1, 2);
                    world.setBlock(i+8, j+6, k+2, b.planks, 1, 2);
                    world.setBlock(i+9, j+6, k+2, b.spruce_stairs, 1, 2);
                    world.setBlock(i+1, j+6, k+3, b.spruce_stairs, 0, 2);
                    world.setBlock(i+2, j+6, k+3, b.planks, 1, 2);
                    world.setBlock(i+3, j+6, k+3, b.planks, 1, 2);
                    world.setBlock(i+4, j+6, k+3, b.planks, 1, 2);
                    world.setBlock(i+5, j+6, k+3, b.planks, 1, 2);
                    world.setBlock(i+6, j+6, k+3, b.planks, 1, 2);
                    world.setBlock(i+7, j+6, k+3, b.planks, 1, 2);
                    world.setBlock(i+8, j+6, k+3, b.planks, 1, 2);
                    world.setBlock(i+9, j+6, k+3, b.spruce_stairs, 1, 2);
                    world.setBlock(i+1, j+6, k+4, b.spruce_stairs, 0, 2);
                    world.setBlock(i+2, j+6, k+4, b.planks, 1, 2);
                    world.setBlock(i+3, j+6, k+4, b.planks, 1, 2);
                    world.setBlock(i+4, j+6, k+4, b.planks, 1, 2);
                    world.setBlock(i+5, j+6, k+4, b.planks, 1, 2);
                    world.setBlock(i+6, j+6, k+4, b.planks, 1, 2);
                    world.setBlock(i+7, j+6, k+4, b.planks, 1, 2);
                    world.setBlock(i+8, j+6, k+4, b.planks, 1, 2);
                    world.setBlock(i+9, j+6, k+4, b.spruce_stairs, 1, 2);
                    world.setBlock(i+1, j+6, k+5, b.spruce_stairs, 0, 2);
                    world.setBlock(i+2, j+6, k+5, b.planks, 1, 2);
                    world.setBlock(i+3, j+6, k+5, b.planks, 1, 2);
                    world.setBlock(i+4, j+6, k+5, b.planks, 1, 2);
                    world.setBlock(i+5, j+6, k+5, b.planks, 1, 2);
                    world.setBlock(i+6, j+6, k+5, b.planks, 1, 2);
                    world.setBlock(i+7, j+6, k+5, b.planks, 1, 2);
                    world.setBlock(i+8, j+6, k+5, b.planks, 1, 2);
                    world.setBlock(i+9, j+6, k+5, b.spruce_stairs, 1, 2);
                    world.setBlock(i+1, j+6, k+6, b.spruce_stairs, 0, 2);
                    world.setBlock(i+2, j+6, k+6, b.planks, 1, 2);
                    world.setBlock(i+3, j+6, k+6, b.planks, 1, 2);
                    world.setBlock(i+4, j+6, k+6, b.planks, 1, 2);
                    world.setBlock(i+5, j+6, k+6, b.planks, 1, 2);
                    world.setBlock(i+6, j+6, k+6, b.planks, 1, 2);
                    world.setBlock(i+7, j+6, k+6, b.planks, 1, 2);
                    world.setBlock(i+8, j+6, k+6, b.planks, 1, 2);
                    world.setBlock(i+9, j+6, k+6, b.spruce_stairs, 1, 2);
                    world.setBlock(i+1, j+6, k+7, b.spruce_stairs, 0, 2);
                    world.setBlock(i+2, j+6, k+7, b.planks, 1, 2);
                    world.setBlock(i+3, j+6, k+7, b.planks, 1, 2);
                    world.setBlock(i+4, j+6, k+7, b.planks, 1, 2);
                    world.setBlock(i+5, j+6, k+7, b.planks, 1, 2);
                    world.setBlock(i+6, j+6, k+7, b.planks, 1, 2);
                    world.setBlock(i+7, j+6, k+7, b.planks, 1, 2);
                    world.setBlock(i+8, j+6, k+7, b.planks, 1, 2);
                    world.setBlock(i+9, j+6, k+7, b.spruce_stairs, 1, 2);
                    world.setBlock(i+1, j+6, k+8, b.spruce_stairs, 0, 2);
                    world.setBlock(i+2, j+6, k+8, b.planks, 1, 2);
                    world.setBlock(i+3, j+6, k+8, b.planks, 1, 2);
                    world.setBlock(i+4, j+6, k+8, b.planks, 1, 2);
                    world.setBlock(i+5, j+6, k+8, b.planks, 1, 2);
                    world.setBlock(i+6, j+6, k+8, b.planks, 1, 2);
                    world.setBlock(i+7, j+6, k+8, b.planks, 1, 2);
                    world.setBlock(i+8, j+6, k+8, b.planks, 1, 2);
                    world.setBlock(i+9, j+6, k+8, b.spruce_stairs, 1, 2);
                    world.setBlock(i+1, j+6, k+9, b.spruce_stairs, 0, 2);
                    world.setBlock(i+2, j+6, k+9, b.spruce_stairs, 3, 2);
                    world.setBlock(i+3, j+6, k+9, b.spruce_stairs, 3, 2);
                    world.setBlock(i+4, j+6, k+9, b.spruce_stairs, 3, 2);
                    world.setBlock(i+5, j+6, k+9, b.spruce_stairs, 3, 2);
                    world.setBlock(i+6, j+6, k+9, b.spruce_stairs, 3, 2);
                    world.setBlock(i+7, j+6, k+9, b.spruce_stairs, 3, 2);
                    world.setBlock(i+8, j+6, k+9, b.spruce_stairs, 3, 2);
                    world.setBlock(i+9, j+6, k+9, b.spruce_stairs, 1, 2);
                    world.setBlock(i+2, j+7, k+2, b.spruce_stairs, 2, 2);
                    world.setBlock(i+3, j+7, k+2, b.spruce_stairs, 2, 2);
                    world.setBlock(i+4, j+7, k+2, b.spruce_stairs, 2, 2);
                    world.setBlock(i+5, j+7, k+2, b.spruce_stairs, 2, 2);
                    world.setBlock(i+6, j+7, k+2, b.spruce_stairs, 2, 2);
                    world.setBlock(i+7, j+7, k+2, b.spruce_stairs, 2, 2);
                    world.setBlock(i+8, j+7, k+2, b.spruce_stairs, 1, 2);
                    world.setBlock(i+2, j+7, k+3, b.spruce_stairs, 0, 2);
                    world.setBlock(i+3, j+7, k+3, b.planks, 1, 2);
                    world.setBlock(i+4, j+7, k+3, b.planks, 1, 2);
                    world.setBlock(i+5, j+7, k+3, b.planks, 1, 2);
                    world.setBlock(i+6, j+7, k+3, b.planks, 1, 2);
                    world.setBlock(i+7, j+7, k+3, b.planks, 1, 2);
                    world.setBlock(i+8, j+7, k+3, b.spruce_stairs, 1, 2);
                    world.setBlock(i+2, j+7, k+4, b.spruce_stairs, 0, 2);
                    world.setBlock(i+3, j+7, k+4, b.planks, 1, 2);
                    world.setBlock(i+4, j+7, k+4, b.planks, 1, 2);
                    world.setBlock(i+5, j+7, k+4, b.planks, 1, 2);
                    world.setBlock(i+6, j+7, k+4, b.planks, 1, 2);
                    world.setBlock(i+7, j+7, k+4, b.planks, 1, 2);
                    world.setBlock(i+8, j+7, k+4, b.spruce_stairs, 1, 2);
                    world.setBlock(i+2, j+7, k+5, b.spruce_stairs, 0, 2);
                    world.setBlock(i+3, j+7, k+5, b.planks, 1, 2);
                    world.setBlock(i+4, j+7, k+5, b.planks, 1, 2);
                    world.setBlock(i+5, j+7, k+5, b.planks, 1, 2);
                    world.setBlock(i+6, j+7, k+5, b.planks, 1, 2);
                    world.setBlock(i+7, j+7, k+5, b.planks, 1, 2);
                    world.setBlock(i+8, j+7, k+5, b.spruce_stairs, 1, 2);
                    world.setBlock(i+2, j+7, k+6, b.spruce_stairs, 0, 2);
                    world.setBlock(i+3, j+7, k+6, b.planks, 1, 2);
                    world.setBlock(i+4, j+7, k+6, b.planks, 1, 2);
                    world.setBlock(i+5, j+7, k+6, b.planks, 1, 2);
                    world.setBlock(i+6, j+7, k+6, b.planks, 1, 2);
                    world.setBlock(i+7, j+7, k+6, b.planks, 1, 2);
                    world.setBlock(i+8, j+7, k+6, b.spruce_stairs, 1, 2);
                    world.setBlock(i+2, j+7, k+7, b.spruce_stairs, 0, 2);
                    world.setBlock(i+3, j+7, k+7, b.planks, 1, 2);
                    world.setBlock(i+4, j+7, k+7, b.planks, 1, 2);
                    world.setBlock(i+5, j+7, k+7, b.planks, 1, 2);
                    world.setBlock(i+6, j+7, k+7, b.planks, 1, 2);
                    world.setBlock(i+7, j+7, k+7, b.planks, 1, 2);
                    world.setBlock(i+8, j+7, k+7, b.spruce_stairs, 1, 2);
                    world.setBlock(i+2, j+7, k+8, b.spruce_stairs, 3, 2);
                    world.setBlock(i+3, j+7, k+8, b.spruce_stairs, 3, 2);
                    world.setBlock(i+4, j+7, k+8, b.spruce_stairs, 3, 2);
                    world.setBlock(i+5, j+7, k+8, b.spruce_stairs, 3, 2);
                    world.setBlock(i+6, j+7, k+8, b.spruce_stairs, 3, 2);
                    world.setBlock(i+7, j+7, k+8, b.spruce_stairs, 3, 2);
                    world.setBlock(i+8, j+7, k+8, b.spruce_stairs, 3, 2);
                    world.setBlock(i+3, j+8, k+3, b.fence, 0, 2);
                    world.setBlock(i+4, j+8, k+3, b.fence, 0, 2);
                    world.setBlock(i+5, j+8, k+3, b.fence, 0, 2);
                    world.setBlock(i+6, j+8, k+3, b.fence, 0, 2);
                    world.setBlock(i+7, j+8, k+3, b.fence, 0, 2);
                    world.setBlock(i+3, j+8, k+4, b.fence, 0, 2);
                    world.setBlock(i+7, j+8, k+4, b.fence, 0, 2);
                    world.setBlock(i+3, j+8, k+5, b.fence, 0, 2);
                    world.setBlock(i+5, j+8, k+5, b.fence, 0, 2);
                    world.setBlock(i+7, j+8, k+5, b.fence, 0, 2);
                    world.setBlock(i+3, j+8, k+6, b.fence, 0, 2);
                    world.setBlock(i+7, j+8, k+6, b.fence, 0, 2);
                    world.setBlock(i+3, j+8, k+7, b.fence, 0, 2);
                    world.setBlock(i+4, j+8, k+7, b.fence, 0, 2);
                    world.setBlock(i+5, j+8, k+7, b.fence, 0, 2);
                    world.setBlock(i+6, j+8, k+7, b.fence, 0, 2);
                    world.setBlock(i+7, j+8, k+7, b.fence, 0, 2);
                    world.setBlock(i+3, j+9, k+3, b.torch, 5, 2);
                    world.setBlock(i+7, j+9, k+3, b.torch, 5, 2);
                    world.setBlock(i+5, j+9, k+5, b.torch, 5, 2);
                    world.setBlock(i+3, j+9, k+7, b.torch, 5, 2);
                    world.setBlock(i+7, j+9, k+7, b.torch, 5, 2);
                }
            }
        }
    }

    public void generateNether(World world, Random random, int chunkX, int chunkZ){}


}